Workbook

Sheet Cover
A1: Production Material Accuracy & Component Tracking Dashboard
A2: (Manufacturing – Footwear Industry)
A3: Production Planning (MES) Portfolio by Riska Amylatul Askiyah
A4: to download this file in xlxs format please check this link: github
A6: 📘 Background
A8: This portfolio presents a practical data-tracking and analysis system built for the footwear manufacturing industry.
A10: Material accuracy is an essential component of production performance. Differences between SAP Qty (planned consumption) and MES Qty (actual scanned consumption) commonly occur due to real operational variations such as scrap, scanning mistakes, missing scans, rework, or deviations in process behavior.
A12: This file demonstrates an end-to-end workflow:
A14: extracting production scan data,
A16: referencing component master data,
A18: validating quantity accuracy,
A20: analyzing variances,
... A201: Build a Power BI version for interactive real-time visibility.

Sheet Sampul
A6: 📘 Latar Belakang
A8: Portfolio ini menyajikan sistem analisis dan tracking data yang digunakan pada lingkungan manufaktur sepatu.
A9: Akurasi material adalah faktor penting yang mempengaruhi efisiensi produksi, kontrol biaya, dan keakuratan stok. Perbedaan antara SAP Qty (rencana konsumsi) dan MES Qty (pemakaian aktual hasil scan) dapat muncul karena scrap, kesalahan scanning, missing scan, rework, ataupun deviasi proses.
A11: File ini menunjukkan alur kerja lengkap:
A13: pengambilan data produksi
A15: referensi ke master material
A17: pengecekan akurasi konsumsi
A19: analisis varians
A21: pembuatan ringkasan & grafik
A23: forecasting target vs aktual
A25: penggunaan formula Excel tingkat lanjut
A27: Semuanya relevan dengan pekerjaan Production Planner, Industrial Engineer, Supply Chain Analyst, dan Data Analyst di industri sepatu.
... A138: Contoh rumus:
A139: =AVERAGE(B2:B4) -> #DIV/0!
A143: 5. Summary_Calculations
A145: Berisi perhitungan otomatis:
A147: Total scan
A149: Overs, shorts, matches
A151: Total SAP Qty & MES Qty
A153: Menggunakan COUNTIF, SUMIFS, dan validasi silang.
A157: 6. Balance_Check
A159: Menggunakan SUMIFS untuk memastikan jumlah total sesuai dan tidak ada ketidaksesuaian perhitungan.
A163: 🔍 Temuan & Insight
A165: Total varians 465 unit menunjukkan perbedaan antara konsumsi teoritis dan aktual.
A167: Jumlah over (44) lebih besar daripada short (31).
A169: Beberapa proses menunjukkan varians negatif seperti Line-4 Sewing dan Line-5 StockFitting — kemungkinan karena missing scan.
... A203: Jika ingin revisi gaya bahasa, penambahan grafik, atau cover professional — tinggal bilang saja.

Sheet ComponentsMaster
A1: ComponentCode | B1: Description | C1: UnitWeight_kg
A2: CMP0001 | B2: Outsole Type 1 | C2: 0.289
A3: CMP0002 | B3: Accessory 2 | C3: 0.297
A4: CMP0003 | B4: Upper Material 3 | C4: 0.599
A5: CMP0004 | B5: Outsole Type 4 | C5: 0.379
A6: CMP0005 | B6: Accessory 5 | C6: 0.32
A7: CMP0006 | B7: Upper Material 6 | C7: 0.129
A8: CMP0007 | B8: Outsole Type 7 | C8: 0.727
A9: CMP0008 | B9: Accessory 8 | C9: 0.402
A10: CMP0009 | B10: Upper Material 9 | C10: 0.875
A11: CMP0010 | B11: Outsole Type 10 | C11: 0.366
A12: CMP0011 | B12: Accessory 11 | C12: 0.403
A13: CMP0012 | B13: Upper Material 12 | C13: 0.216
... A31: CMP0030 | B31: Upper Material 30 | C31: 0.614

Sheet RawData
A1: Date | B1: Shift | C1: Line | D1: Process | E1: MES_Code | F1: ComponentCode | G1: Component_Desc | H1: SAP_Qty | I1: MES_Qty | J1: Difference | K1: Status | L1: ScanTime | M1: Remarks
A2: 45972 | B2: B | C2: Line-4 | D2: Cutting | E2: HC | F2: CMP0004 | G2: =VLOOKUP(F2,ComponentsMaster!$A:$C,2,FALSE) -> Outsole Type 4 | H2: 497 | I2: 503 | J2: =I2-H2 -> 6 | K2: =IF(J2=0,"Match",IF(J2<0,"Short","Over")) -> Over | L2: 2025-11-11 08:39:00 | M2: Check
A3: 45963 | B3: A | C3: Line-4 | D3: Sewing | E3: HU | F3: CMP0027 | G3: =VLOOKUP(F3,ComponentsMaster!$A:$C,2,FALSE) -> Upper Material 27 | H3: 258 | I3: 251 | J3: =I3-H3 -> -7 | K3: =IF(J3=0,"Match",IF(J3<0,"Short","Over")) -> Short | L3: 2025-11-02 14:01:00 | M3: Check
A4: 45962 | B4: A | C4: Line-5 | D4: Cutting | E4: HC | F4: CMP0008 | G4: =VLOOKUP(F4,ComponentsMaster!$A:$C,2,FALSE) -> Accessory 8 | H4: 367 | I4: 369 | J4: =I4-H4 -> 2 | K4: =IF(J4=0,"Match",IF(J4<0,"Short","Over")) -> Over | L4: 2025-11-01 12:37:00 | M4: OK
A5: 45973 | B5: A | C5: Line-4 | D5: Cutting | E5: HC | F5: CMP0018 | G5: =VLOOKUP(F5,ComponentsMaster!$A:$C,2,FALSE) -> Upper Material 18 | H5: 433 | I5: 441 | J5: =I5-H5 -> 8 | K5: =IF(J5=0,"Match",IF(J5<0,"Short","Over")) -> Over | L5: 2025-11-12 15:42:00 | M5: Check
A6: 45966 | B6: B | C6: Line-5 | D6: StockFitting | E6: HS | F6: CMP0019 | G6: =VLOOKUP(F6,ComponentsMaster!$A:$C,2,FALSE) -> Outsole Type 19 | H6: 129 | I6: 125 | J6: =I6-H6 -> -4 | K6: =IF(J6=0,"Match",IF(J6<0,"Short","Over")) -> Short | L6: 2025-11-05 06:05:00 | M6: OK
A7: 45965 | B7: B | C7: Line-3 | D7: Cutting | E7: HC | F7: CMP0013 | G7: =VLOOKUP(F7,ComponentsMaster!$A:$C,2,FALSE) -> Outsole Type 13 | H7: 171 | I7: 169 | J7: =I7-H7 -> -2 | K7: =IF(J7=0,"Match",IF(J7<0,"Short","Over")) -> Short | L7: 2025-11-04 16:27:00 | M7: OK
A8: 45965 | B8: B | C8: Line-5 | D8: Sewing | E8: HU | F8: CMP0018 | G8: =VLOOKUP(F8,ComponentsMaster!$A:$C,2,FALSE) -> Upper Material 18 | H8: 492 | I8: 483 | J8: =I8-H8 -> -9 | K8: =IF(J8=0,"Match",IF(J8<0,"Short","Over")) -> Short | L8: 2025-11-04 08:55:00 | M8: Check
A9: 45964 | B9: C | C9: Line-1 | D9: StockFitting | E9: HS | F9: CMP0016 | G9: =VLOOKUP(F9,ComponentsMaster!$A:$C,2,FALSE) -> Outsole Type 16 | H9: 133 | I9: 145 | J9: =I9-H9 -> 12 | K9: =IF(J9=0,"Match",IF(J9<0,"Short","Over")) -> Over | L9: 2025-11-03 13:11:00 | M9: Check
A10: 45973 | B10: B | C10: Line-1 | D10: Assembling | E10: FG | F10: CMP0029 | G10: =VLOOKUP(F10,ComponentsMaster!$A:$C,2,FALSE) -> Accessory 29 | H10: 459 | I10: 462 | J10: =I10-H10 -> 3 | K10: =IF(J10=0,"Match",IF(J10<0,"Short","Over")) -> Over | L10: 2025-11-12 06:16:00 | M10: OK
A11: 45963 | B11: A | C11: Line-5 | D11: Sewing | E11: HU | F11: CMP0007 | G11: =VLOOKUP(F11,ComponentsMaster!$A:$C,2,FALSE) -> Outsole Type 7 | H11: 465 | I11: 455 | J11: =I11-H11 -> -10 | K11: =IF(J11=0,"Match",IF(J11<0,"Short","Over")) -> Short | L11: 2025-11-02 12:20:00 | M11: Check
A12: 45972 | B12: B | C12: Line-3 | D12: Sewing | E12: HU | F12: CMP0022 | G12: =VLOOKUP(F12,ComponentsMaster!$A:$C,2,FALSE) -> Outsole Type 22 | H12: 140 | I12: 146 | J12: =I12-H12 -> 6 | K12: =IF(J12=0,"Match",IF(J12<0,"Short","Over")) -> Over | L12: 2025-11-11 09:29:00 | M12: Check
A13: 45973 | B13: B | C13: Line-3 | D13: Assembling | E13: FG | F13: CMP0008 | G13: =VLOOKUP(F13,ComponentsMaster!$A:$C,2,FALSE) -> Accessory 8 | H13: 261 | I13: 268 | J13: =I13-H13 -> 7 | K13: =IF(J13=0,"Match",IF(J13<0,"Short","Over")) -> Over | L13: 2025-11-12 11:21:00 | M13: Check
... A81: 45965 | B81: A | C81: Line-1 | D81: Assembling | E81: FG | F81: CMP0024 | G81: =VLOOKUP(F81,ComponentsMaster!$A:$C,2,FALSE) -> Upper Material 24 | H81: 360 | I81: 351 | J81: =I81-H81 -> -9 | K81: =IF(J81=0,"Match",IF(J81<0,"Short","Over")) -> Short | L81: 2025-11-04 10:56:00 | M81: Check

Sheet Pivot Table
A3: Row Labels | B3: Count of Status
A4: Match | B4: 5
A5: Over | B5: 44
A6: Short | B6: 31
A7: Grand Total | B7: 80
A10: Row Labels | B10: Count of Line | C10: Sum of Difference
A11: Line-1 | B11: 17 | C11: 48
A12: Assembling | B12: 6 | C12: 14
A13: Cutting | B13: 5 | C13: 14
A14: Sewing | B14: 4 | C14: 5
A15: StockFitting | B15: 2 | C15: 15
A16: Line-2 | B16: 16 | C16: 59
A17: Assembling | B17: 6 | C17: 16
A18: Cutting | B18: 3 | C18: 11
A19: Sewing | B19: 5 | C19: 11
A20: StockFitting | B20: 2 | C20: 21
A21: Line-3 | B21: 14 | C21: 44
A22: Assembling | B22: 7 | C22: 20
... A35: Grand Total | B35: 80 | C35: 169
A38: Row Labels | B38: Sum of SAP_Qty | C38: Sum of MES_Qty
A39: Assembling | B39: 8197 | C39: 8254
A40: Cutting | B40: 6318 | C40: 6396
A41: Sewing | B41: 6037 | C41: 6047
A42: StockFitting | B42: 2694 | C42: 2718
A43: Grand Total | B43: 23246 | C43: 23415
A46: Row Labels | B46: Sum of Difference
A47: 45962 | B47: -9
A48: Line-1 | B48: 3
A49: Assembling | B49: 11
A50: Cutting | B50: -8
A51: Line-2 | B51: -6
A52: Cutting | B52: -6
A53: Line-3 | B53: -7
A54: Cutting | B54: -7
A55: Line-4 | B55: 3
A56: Cutting | B56: 3
A57: Line-5 | B57: -2
A58: Cutting | B58: 2
A59: StockFitting | B59: -4
A60: 45963 | B60: 19
...

Sheet Forecast Target&Actual
A1: Date | B1: Target_per_day | C1: Actual_per_day | D1: Moving Average Target 3 days | E1: error | F1: Moving Average Actual 1 Week | G1: error
A2: 45962 | B2: =VLOOKUP(A2,RawDataTable[#All],8,FALSE) -> 367 | C2: =VLOOKUP(A2,RawDataTable[#All],9,FALSE) -> 369 | D2: #N/A | E2: #N/A | F2: #N/A | G2: #N/A
A3: 45963 | B3: =VLOOKUP(A3,RawDataTable[#All],8,FALSE) -> 258 | C3: =VLOOKUP(A3,RawDataTable[#All],9,FALSE) -> 251 | D3: #N/A | E3: #N/A | F3: #N/A | G3: #N/A
A4: 45964 | B4: =VLOOKUP(A4,RawDataTable[#All],8,FALSE) -> 133 | C4: =VLOOKUP(A4,RawDataTable[#All],9,FALSE) -> 145 | D4: =AVERAGE(B2:B4) -> 252.66667 | E4: #N/A | F4: =AVERAGE(C2:C4) -> 255 | G4: #N/A
A5: 45965 | B5: =VLOOKUP(A5,RawDataTable[#All],8,FALSE) -> 171 | C5: =VLOOKUP(A5,RawDataTable[#All],9,FALSE) -> 169 | D5: =AVERAGE(B3:B5) -> 187.33333 | E5: #N/A | F5: =AVERAGE(C3:C5) -> 188.33333 | G5: #N/A
A6: 45966 | B6: =VLOOKUP(A6,RawDataTable[#All],8,FALSE) -> 129 | C6: =VLOOKUP(A6,RawDataTable[#All],9,FALSE) -> 125 | D6: =AVERAGE(B4:B6) -> 144.33333 | E6: =SQRT(SUMXMY2(B4:B6,D4:D6)/3) -> 70.289876 | F6: =AVERAGE(C4:C6) -> 146.33333 | G6: =SQRT(SUMXMY2(C4:C6,F4:F6)/3) -> 65.647769
A7: 45967 | B7: =VLOOKUP(A7,RawDataTable[#All],8,FALSE) -> 166 | C7: =VLOOKUP(A7,RawDataTable[#All],9,FALSE) -> 165 | D7: =AVERAGE(B5:B7) -> 155.33333 | E7: =SQRT(SUMXMY2(B5:B7,D5:D7)/3) -> 14.325579 | F7: =AVERAGE(C5:C7) -> 153 | G7: =SQRT(SUMXMY2(C5:C7,F5:F7)/3) -> 18.008229
A8: 45968 | B8: =VLOOKUP(A8,RawDataTable[#All],8,FALSE) -> 220 | C8: =VLOOKUP(A8,RawDataTable[#All],9,FALSE) -> 221 | D8: =AVERAGE(B6:B8) -> 171.66667 | E8: =SQRT(SUMXMY2(B6:B8,D6:D8)/3) -> 29.916551 | F8: =AVERAGE(C6:C8) -> 170.33333 | G8: =SQRT(SUMXMY2(C6:C8,F6:F8)/3) -> 32.487034
A9: 45969 | B9: =VLOOKUP(A9,RawDataTable[#All],8,FALSE) -> 489 | C9: =VLOOKUP(A9,RawDataTable[#All],9,FALSE) -> 488 | D9: =AVERAGE(B7:B9) -> 291.66667 | E9: =SQRT(SUMXMY2(B7:B9,D7:D9)/3) -> 117.45969 | F9: =AVERAGE(C7:C9) -> 291.33333 | G9: =SQRT(SUMXMY2(C7:C9,F7:F9)/3) -> 117.45764
A10: 45970 | B10: =VLOOKUP(A10,RawDataTable[#All],8,FALSE) -> 62 | C10: =VLOOKUP(A10,RawDataTable[#All],9,FALSE) -> 73 | D10: =AVERAGE(B8:B10) -> 257 | E10: =SQRT(SUMXMY2(B8:B10,D8:D10)/3) -> 162.58491 | F10: =AVERAGE(C8:C10) -> 260.66667 | G10: =SQRT(SUMXMY2(C8:C10,F8:F10)/3) -> 159.64927
A11: 45971 | B11: =VLOOKUP(A11,RawDataTable[#All],8,FALSE) -> 427 | C11: =VLOOKUP(A11,RawDataTable[#All],9,FALSE) -> 423 | D11: =AVERAGE(B9:B11) -> 326 | E11: =SQRT(SUMXMY2(B9:B11,D9:D11)/3) -> 170.45669 | F11: =AVERAGE(C9:C11) -> 328 | G11: =SQRT(SUMXMY2(C9:C11,F9:F11)/3) -> 166.25438
A12: 45972 | B12: =VLOOKUP(A12,RawDataTable[#All],8,FALSE) -> 497 | C12: =VLOOKUP(A12,RawDataTable[#All],9,FALSE) -> 503 | D12: =AVERAGE(B10:B12) -> 328.66667 | E12: =SQRT(SUMXMY2(B10:B12,D10:D12)/3) -> 159.75201 | F12: =AVERAGE(C10:C12) -> 333 | G12: =SQRT(SUMXMY2(C10:C12,F10:F12)/3) -> 156.14499
A13: 45973 | B13: =VLOOKUP(A13,RawDataTable[#All],8,FALSE) -> 433 | C13: =VLOOKUP(A13,RawDataTable[#All],9,FALSE) -> 441 | D13: =AVERAGE(B11:B13) -> 452.33333 | E13: =SQRT(SUMXMY2(B11:B13,D11:D13)/3) -> 113.88721 | F13: =AVERAGE(C11:C13) -> 455.66667 | G13: =SQRT(SUMXMY2(C11:C13,F11:F13)/3) -> 112.75358
A14: 45974 | B14: =VLOOKUP(A14,RawDataTable[#All],8,FALSE) -> 152 | C14: =VLOOKUP(A14,RawDataTable[#All],9,FALSE) -> 148 | D14: =AVERAGE(B12:B14) -> 360.66667 | E14: =SQRT(SUMXMY2(B12:B14,D12:D14)/3) -> 155.18985 | F14: =AVERAGE(C12:C14) -> 364 | G14: =SQRT(SUMXMY2(C12:C14,F12:F14)/3) -> 158.92463
A15: 45975 | B15: =VLOOKUP(A15,RawDataTable[#All],8,FALSE) -> 468 | C15: =VLOOKUP(A15,RawDataTable[#All],9,FALSE) -> 471 | D15: =AVERAGE(B13:B15) -> 351 | E15: =SQRT(SUMXMY2(B13:B15,D13:D15)/3) -> 138.56954 | F15: =AVERAGE(C13:C15) -> 353.33333 | G15: =SQRT(SUMXMY2(C13:C15,F13:F15)/3) -> 142.26332

Sheet Summary_Calculations
A1: KPI | B1: Value
A2: Total Scans (records) | B2: =COUNTA(RawData!A2:A81) -> 80
A3: Total SAP Qty | B3: =SUM(RawData!H2:H81) -> 23246
A4: Total MES Qty | B4: =SUM(RawData!I2:I81) -> 23415
A5: Total Differences (abs) | B5: =SUMPRODUCT(ABS(RawData!J2:J81)) -> 465
A6: Matches | B6: =COUNTIF(RawData!K2:K81,"Match") -> 5
A7: Shorts | B7: =COUNTIF(RawData!K2:K81,"Short") -> 31
A8: Overs | B8: =COUNTIF(RawData!K2:K81,"Over") -> 44

Sheet Balance_Check
A1: Line | B1: Process | C1: Total_SAP_Qty | D1: Total_MES_Qty | E1: Diff
A2: Line-1 | B2: Cutting | C2: =SUMIFS(RawData!H2:H81,RawData!C2:C81,$A2,RawData!D2:D81,$B2) -> 1091 | D2: =SUMIFS(RawData!I2:I81,RawData!C2:C81,$A2,RawData!D2:D81,$B2) -> 1105 | E2: =D2-C2 -> 14
A3: Line-1 | B3: Sewing | C3: =SUMIFS(RawData!H2:H81,RawData!C2:C81,$A3,RawData!D2:D81,$B3) -> 752 | D3: =SUMIFS(RawData!I2:I81,RawData!C2:C81,$A3,RawData!D2:D81,$B3) -> 757 | E3: =D3-C3 -> 5
A4: Line-1 | B4: StockFitting | C4: =SUMIFS(RawData!H2:H81,RawData!C2:C81,$A4,RawData!D2:D81,$B4) -> 601 | D4: =SUMIFS(RawData!I2:I81,RawData!C2:C81,$A4,RawData!D2:D81,$B4) -> 616 | E4: =D4-C4 -> 15
A5: Line-1 | B5: Assembling | C5: =SUMIFS(RawData!H2:H81,RawData!C2:C81,$A5,RawData!D2:D81,$B5) -> 2206 | D5: =SUMIFS(RawData!I2:I81,RawData!C2:C81,$A5,RawData!D2:D81,$B5) -> 2220 | E5: =D5-C5 -> 14
A6: Line-2 | B6: Cutting | C6: =SUMIFS(RawData!H2:H81,RawData!C2:C81,$A6,RawData!D2:D81,$B6) -> 891 | D6: =SUMIFS(RawData!I2:I81,RawData!C2:C81,$A6,RawData!D2:D81,$B6) -> 902 | E6: =D6-C6 -> 11
A7: Line-2 | B7: Sewing | C7: =SUMIFS(RawData!H2:H81,RawData!C2:C81,$A7,RawData!D2:D81,$B7) -> 1525 | D7: =SUMIFS(RawData!I2:I81,RawData!C2:C81,$A7,RawData!D2:D81,$B7) -> 1536 | E7: =D7-C7 -> 11
A8: Line-2 | B8: StockFitting | C8: =SUMIFS(RawData!H2:H81,RawData!C2:C81,$A8,RawData!D2:D81,$B8) -> 756 | D8: =SUMIFS(RawData!I2:I81,RawData!C2:C81,$A8,RawData!D2:D81,$B8) -> 777 | E8: =D8-C8 -> 21
A9: Line-2 | B9: Assembling | C9: =SUMIFS(RawData!H2:H81,RawData!C2:C81,$A9,RawData!D2:D81,$B9) -> 2368 | D9: =SUMIFS(RawData!I2:I81,RawData!C2:C81,$A9,RawData!D2:D81,$B9) -> 2384 | E9: =D9-C9 -> 16
A10: Line-3 | B10: Cutting | C10: =SUMIFS(RawData!H2:H81,RawData!C2:C81,$A10,RawData!D2:D81,$B10) -> 659 | D10: =SUMIFS(RawData!I2:I81,RawData!C2:C81,$A10,RawData!D2:D81,$B10) -> 664 | E10: =D10-C10 -> 5
A11: Line-3 | B11: Sewing | C11: =SUMIFS(RawData!H2:H81,RawData!C2:C81,$A11,RawData!D2:D81,$B11) -> 433 | D11: =SUMIFS(RawData!I2:I81,RawData!C2:C81,$A11,RawData!D2:D81,$B11) -> 452 | E11: =D11-C11 -> 19
A12: Line-3 | B12: StockFitting | C12: =SUMIFS(RawData!H2:H81,RawData!C2:C81,$A12,RawData!D2:D81,$B12) -> 0 | D12: =SUMIFS(RawData!I2:I81,RawData!C2:C81,$A12,RawData!D2:D81,$B12) -> 0 | E12: =D12-C12 -> 0
A13: Line-3 | B13: Assembling | C13: =SUMIFS(RawData!H2:H81,RawData!C2:C81,$A13,RawData!D2:D81,$B13) -> 1646 | D13: =SUMIFS(RawData!I2:I81,RawData!C2:C81,$A13,RawData!D2:D81,$B13) -> 1666 | E13: =D13-C13 -> 20
A14: Line-4 | B14: Cutting | C14: =SUMIFS(RawData!H2:H81,RawData!C2:C81,$A14,RawData!D2:D81,$B14) -> 1563 | D14: =SUMIFS(RawData!I2:I81,RawData!C2:C81,$A14,RawData!D2:D81,$B14) -> 1586 | E14: =D14-C14 -> 23
A15: Line-4 | B15: Sewing | C15: =SUMIFS(RawData!H2:H81,RawData!C2:C81,$A15,RawData!D2:D81,$B15) -> 1016 | D15: =SUMIFS(RawData!I2:I81,RawData!C2:C81,$A15,RawData!D2:D81,$B15) -> 990 | E15: =D15-C15 -> -26
A16: Line-4 | B16: StockFitting | C16: =SUMIFS(RawData!H2:H81,RawData!C2:C81,$A16,RawData!D2:D81,$B16) -> 419 | D16: =SUMIFS(RawData!I2:I81,RawData!C2:C81,$A16,RawData!D2:D81,$B16) -> 415 | E16: =D16-C16 -> -4
A17: Line-4 | B17: Assembling | C17: =SUMIFS(RawData!H2:H81,RawData!C2:C81,$A17,RawData!D2:D81,$B17) -> 919 | D17: =SUMIFS(RawData!I2:I81,RawData!C2:C81,$A17,RawData!D2:D81,$B17) -> 923 | E17: =D17-C17 -> 4
A18: Line-5 | B18: Cutting | C18: =SUMIFS(RawData!H2:H81,RawData!C2:C81,$A18,RawData!D2:D81,$B18) -> 2114 | D18: =SUMIFS(RawData!I2:I81,RawData!C2:C81,$A18,RawData!D2:D81,$B18) -> 2139 | E18: =D18-C18 -> 25
A19: Line-5 | B19: Sewing | C19: =SUMIFS(RawData!H2:H81,RawData!C2:C81,$A19,RawData!D2:D81,$B19) -> 2311 | D19: =SUMIFS(RawData!I2:I81,RawData!C2:C81,$A19,RawData!D2:D81,$B19) -> 2312 | E19: =D19-C19 -> 1
A20: Line-5 | B20: StockFitting | C20: =SUMIFS(RawData!H2:H81,RawData!C2:C81,$A20,RawData!D2:D81,$B20) -> 918 | D20: =SUMIFS(RawData!I2:I81,RawData!C2:C81,$A20,RawData!D2:D81,$B20) -> 910 | E20: =D20-C20 -> -8
A21: Line-5 | B21: Assembling | C21: =SUMIFS(RawData!H2:H81,RawData!C2:C81,$A21,RawData!D2:D81,$B21) -> 1058 | D21: =SUMIFS(RawData!I2:I81,RawData!C2:C81,$A21,RawData!D2:D81,$B21) -> 1061 | E21: =D21-C21 -> 3

Sheet Sheet3
